[2022-09-13 13:36:21,288] {taskinstance.py:826} INFO - Dependencies all met for <TaskInstance: postgres_dag.insert_records 2022-09-13T13:36:16.862457+00:00 [queued]>
[2022-09-13 13:36:21,341] {taskinstance.py:826} INFO - Dependencies all met for <TaskInstance: postgres_dag.insert_records 2022-09-13T13:36:16.862457+00:00 [queued]>
[2022-09-13 13:36:21,342] {taskinstance.py:1017} INFO - 
--------------------------------------------------------------------------------
[2022-09-13 13:36:21,343] {taskinstance.py:1018} INFO - Starting attempt 1 of 3
[2022-09-13 13:36:21,344] {taskinstance.py:1019} INFO - 
--------------------------------------------------------------------------------
[2022-09-13 13:36:21,375] {taskinstance.py:1038} INFO - Executing <Task(PostgresOperator): insert_records> on 2022-09-13T13:36:16.862457+00:00
[2022-09-13 13:36:21,381] {standard_task_runner.py:51} INFO - Started process 39561 to run task
[2022-09-13 13:36:21,398] {standard_task_runner.py:75} INFO - Running: ['airflow', 'tasks', 'run', 'postgres_dag', 'insert_records', '2022-09-13T13:36:16.862457+00:00', '--job-id', '24', '--pool', 'default_pool', '--raw', '--subdir', 'DAGS_FOLDER/dag_with_postgres.py', '--cfg-path', '/tmp/tmpzmrt1gej']
[2022-09-13 13:36:21,410] {standard_task_runner.py:76} INFO - Job 24: Subtask insert_records
[2022-09-13 13:36:21,533] {logging_mixin.py:103} INFO - Running <TaskInstance: postgres_dag.insert_records 2022-09-13T13:36:16.862457+00:00 [running]> on host 27377494ab8b
[2022-09-13 13:36:21,670] {taskinstance.py:1232} INFO - Exporting the following env vars:
AIRFLOW_CTX_DAG_OWNER=Dave
AIRFLOW_CTX_DAG_ID=postgres_dag
AIRFLOW_CTX_TASK_ID=insert_records
AIRFLOW_CTX_EXECUTION_DATE=2022-09-13T13:36:16.862457+00:00
AIRFLOW_CTX_DAG_RUN_ID=manual__2022-09-13T13:36:16.862457+00:00
[2022-09-13 13:36:21,673] {postgres.py:69} INFO - Executing: 
            INSERT INTO employee (emp_id,first_name,last_name,designation)
            VALUES ('l101','Bayo','Lanre','Software-developer');
            INSERT INTO employee (emp_id,first_name,last_name,designation)
            VALUES ('l1201','Diaz','Mora','Data Scientist');
            INSERT INTO employee (emp_id,first_name,last_name,designation)
            VALUES ('l4101','Chris','Muff','scrum-master');
            INSERT INTO employee (emp_id,first_name,last_name,designation)
            VALUES ('l1301','Inder','Ajith','Manager');
        
[2022-09-13 13:36:21,712] {base.py:74} INFO - Using connection to: id: local_postgres. Host: 0.0.0.0, Port: 5432, Schema: airflow, Login: postgres, Password: XXXXXXXX, extra: None
[2022-09-13 13:36:21,718] {taskinstance.py:1396} ERROR - could not connect to server: Connection refused
	Is the server running on host "0.0.0.0" and accepting
	TCP/IP connections on port 5432?
Traceback (most recent call last):
  File "/home/airflow/.local/lib/python3.6/site-packages/airflow/models/taskinstance.py", line 1086, in _run_raw_task
    self._prepare_and_execute_task_with_callbacks(context, task)
  File "/home/airflow/.local/lib/python3.6/site-packages/airflow/models/taskinstance.py", line 1260, in _prepare_and_execute_task_with_callbacks
    result = self._execute_task(context, task_copy)
  File "/home/airflow/.local/lib/python3.6/site-packages/airflow/models/taskinstance.py", line 1300, in _execute_task
    result = task_copy.execute(context=context)
  File "/home/airflow/.local/lib/python3.6/site-packages/airflow/providers/postgres/operators/postgres.py", line 71, in execute
    self.hook.run(self.sql, self.autocommit, parameters=self.parameters)
  File "/home/airflow/.local/lib/python3.6/site-packages/airflow/hooks/dbapi.py", line 173, in run
    with closing(self.get_conn()) as conn:
  File "/home/airflow/.local/lib/python3.6/site-packages/airflow/providers/postgres/hooks/postgres.py", line 108, in get_conn
    self.conn = psycopg2.connect(**conn_args)
  File "/home/airflow/.local/lib/python3.6/site-packages/psycopg2/__init__.py", line 127, in connect
    conn = _connect(dsn, connection_factory=connection_factory, **kwasync)
psycopg2.OperationalError: could not connect to server: Connection refused
	Is the server running on host "0.0.0.0" and accepting
	TCP/IP connections on port 5432?

[2022-09-13 13:36:21,734] {taskinstance.py:1440} INFO - Marking task as UP_FOR_RETRY. dag_id=postgres_dag, task_id=insert_records, execution_date=20220913T133616, start_date=20220913T133621, end_date=20220913T133621
[2022-09-13 13:36:21,885] {local_task_job.py:118} INFO - Task exited with return code 1
