[2022-09-13 13:37:24,487] {taskinstance.py:826} INFO - Dependencies all met for <TaskInstance: postgres_dag.create_employee_table 2022-09-12T03:00:00+00:00 [queued]>
[2022-09-13 13:37:24,603] {taskinstance.py:826} INFO - Dependencies all met for <TaskInstance: postgres_dag.create_employee_table 2022-09-12T03:00:00+00:00 [queued]>
[2022-09-13 13:37:24,605] {taskinstance.py:1017} INFO - 
--------------------------------------------------------------------------------
[2022-09-13 13:37:24,606] {taskinstance.py:1018} INFO - Starting attempt 2 of 3
[2022-09-13 13:37:24,607] {taskinstance.py:1019} INFO - 
--------------------------------------------------------------------------------
[2022-09-13 13:37:24,673] {taskinstance.py:1038} INFO - Executing <Task(PostgresOperator): create_employee_table> on 2022-09-12T03:00:00+00:00
[2022-09-13 13:37:24,717] {standard_task_runner.py:51} INFO - Started process 40708 to run task
[2022-09-13 13:37:24,735] {standard_task_runner.py:75} INFO - Running: ['airflow', 'tasks', 'run', 'postgres_dag', 'create_employee_table', '2022-09-12T03:00:00+00:00', '--job-id', '30', '--pool', 'default_pool', '--raw', '--subdir', 'DAGS_FOLDER/dag_with_postgres.py', '--cfg-path', '/tmp/tmp0vzd2fwe']
[2022-09-13 13:37:24,748] {standard_task_runner.py:76} INFO - Job 30: Subtask create_employee_table
[2022-09-13 13:37:24,962] {logging_mixin.py:103} INFO - Running <TaskInstance: postgres_dag.create_employee_table 2022-09-12T03:00:00+00:00 [running]> on host 27377494ab8b
[2022-09-13 13:37:25,090] {taskinstance.py:1232} INFO - Exporting the following env vars:
AIRFLOW_CTX_DAG_OWNER=Dave
AIRFLOW_CTX_DAG_ID=postgres_dag
AIRFLOW_CTX_TASK_ID=create_employee_table
AIRFLOW_CTX_EXECUTION_DATE=2022-09-12T03:00:00+00:00
AIRFLOW_CTX_DAG_RUN_ID=scheduled__2022-09-12T03:00:00+00:00
[2022-09-13 13:37:25,093] {postgres.py:69} INFO - Executing: 
            create table if not exists employee(
                emp_id varchar,
                first_name varchar,
                last_name varchar,
                designation varchar
                primary key (emp_id)
            )
        
[2022-09-13 13:37:25,132] {base.py:74} INFO - Using connection to: id: local_postgres. Host: 0.0.0.0, Port: 5432, Schema: airflow, Login: postgres, Password: XXXXXXXX, extra: None
[2022-09-13 13:37:25,142] {taskinstance.py:1396} ERROR - could not connect to server: Connection refused
	Is the server running on host "0.0.0.0" and accepting
	TCP/IP connections on port 5432?
Traceback (most recent call last):
  File "/home/airflow/.local/lib/python3.6/site-packages/airflow/models/taskinstance.py", line 1086, in _run_raw_task
    self._prepare_and_execute_task_with_callbacks(context, task)
  File "/home/airflow/.local/lib/python3.6/site-packages/airflow/models/taskinstance.py", line 1260, in _prepare_and_execute_task_with_callbacks
    result = self._execute_task(context, task_copy)
  File "/home/airflow/.local/lib/python3.6/site-packages/airflow/models/taskinstance.py", line 1300, in _execute_task
    result = task_copy.execute(context=context)
  File "/home/airflow/.local/lib/python3.6/site-packages/airflow/providers/postgres/operators/postgres.py", line 71, in execute
    self.hook.run(self.sql, self.autocommit, parameters=self.parameters)
  File "/home/airflow/.local/lib/python3.6/site-packages/airflow/hooks/dbapi.py", line 173, in run
    with closing(self.get_conn()) as conn:
  File "/home/airflow/.local/lib/python3.6/site-packages/airflow/providers/postgres/hooks/postgres.py", line 108, in get_conn
    self.conn = psycopg2.connect(**conn_args)
  File "/home/airflow/.local/lib/python3.6/site-packages/psycopg2/__init__.py", line 127, in connect
    conn = _connect(dsn, connection_factory=connection_factory, **kwasync)
psycopg2.OperationalError: could not connect to server: Connection refused
	Is the server running on host "0.0.0.0" and accepting
	TCP/IP connections on port 5432?

[2022-09-13 13:37:25,153] {taskinstance.py:1440} INFO - Marking task as UP_FOR_RETRY. dag_id=postgres_dag, task_id=create_employee_table, execution_date=20220912T030000, start_date=20220913T133724, end_date=20220913T133725
[2022-09-13 13:37:25,287] {local_task_job.py:118} INFO - Task exited with return code 1
[2022-09-13 13:40:12,915] {taskinstance.py:826} INFO - Dependencies all met for <TaskInstance: postgres_dag.create_employee_table 2022-09-12T03:00:00+00:00 [queued]>
[2022-09-13 13:40:12,990] {taskinstance.py:826} INFO - Dependencies all met for <TaskInstance: postgres_dag.create_employee_table 2022-09-12T03:00:00+00:00 [queued]>
[2022-09-13 13:40:12,991] {taskinstance.py:1017} INFO - 
--------------------------------------------------------------------------------
[2022-09-13 13:40:12,993] {taskinstance.py:1018} INFO - Starting attempt 2 of 3
[2022-09-13 13:40:12,995] {taskinstance.py:1019} INFO - 
--------------------------------------------------------------------------------
[2022-09-13 13:40:13,029] {taskinstance.py:1038} INFO - Executing <Task(PostgresOperator): create_employee_table> on 2022-09-12T03:00:00+00:00
[2022-09-13 13:40:13,042] {standard_task_runner.py:51} INFO - Started process 43567 to run task
[2022-09-13 13:40:13,063] {standard_task_runner.py:75} INFO - Running: ['airflow', 'tasks', 'run', 'postgres_dag', 'create_employee_table', '2022-09-12T03:00:00+00:00', '--job-id', '50', '--pool', 'default_pool', '--raw', '--subdir', 'DAGS_FOLDER/dag_with_postgres.py', '--cfg-path', '/tmp/tmpy07bt_48']
[2022-09-13 13:40:13,077] {standard_task_runner.py:76} INFO - Job 50: Subtask create_employee_table
[2022-09-13 13:40:13,198] {logging_mixin.py:103} INFO - Running <TaskInstance: postgres_dag.create_employee_table 2022-09-12T03:00:00+00:00 [running]> on host 27377494ab8b
[2022-09-13 13:40:13,330] {taskinstance.py:1232} INFO - Exporting the following env vars:
AIRFLOW_CTX_DAG_OWNER=Dave
AIRFLOW_CTX_DAG_ID=postgres_dag
AIRFLOW_CTX_TASK_ID=create_employee_table
AIRFLOW_CTX_EXECUTION_DATE=2022-09-12T03:00:00+00:00
AIRFLOW_CTX_DAG_RUN_ID=scheduled__2022-09-12T03:00:00+00:00
[2022-09-13 13:40:13,334] {postgres.py:69} INFO - Executing: 
            create table if not exists employee(
                emp_id varchar,
                first_name varchar,
                last_name varchar,
                designation varchar
                primary key (emp_id)
            )
        
[2022-09-13 13:40:13,403] {base.py:74} INFO - Using connection to: id: local_postgres. Host: host.docker.internal, Port: 5432, Schema: airflow, Login: postgres, Password: XXXXXXXX, extra: None
[2022-09-13 13:40:13,441] {taskinstance.py:1396} ERROR - FATAL:  database "airflow" does not exist
Traceback (most recent call last):
  File "/home/airflow/.local/lib/python3.6/site-packages/airflow/models/taskinstance.py", line 1086, in _run_raw_task
    self._prepare_and_execute_task_with_callbacks(context, task)
  File "/home/airflow/.local/lib/python3.6/site-packages/airflow/models/taskinstance.py", line 1260, in _prepare_and_execute_task_with_callbacks
    result = self._execute_task(context, task_copy)
  File "/home/airflow/.local/lib/python3.6/site-packages/airflow/models/taskinstance.py", line 1300, in _execute_task
    result = task_copy.execute(context=context)
  File "/home/airflow/.local/lib/python3.6/site-packages/airflow/providers/postgres/operators/postgres.py", line 71, in execute
    self.hook.run(self.sql, self.autocommit, parameters=self.parameters)
  File "/home/airflow/.local/lib/python3.6/site-packages/airflow/hooks/dbapi.py", line 173, in run
    with closing(self.get_conn()) as conn:
  File "/home/airflow/.local/lib/python3.6/site-packages/airflow/providers/postgres/hooks/postgres.py", line 108, in get_conn
    self.conn = psycopg2.connect(**conn_args)
  File "/home/airflow/.local/lib/python3.6/site-packages/psycopg2/__init__.py", line 127, in connect
    conn = _connect(dsn, connection_factory=connection_factory, **kwasync)
psycopg2.OperationalError: FATAL:  database "airflow" does not exist

[2022-09-13 13:40:13,457] {taskinstance.py:1440} INFO - Marking task as UP_FOR_RETRY. dag_id=postgres_dag, task_id=create_employee_table, execution_date=20220912T030000, start_date=20220913T134012, end_date=20220913T134013
[2022-09-13 13:40:13,593] {local_task_job.py:118} INFO - Task exited with return code 1
[2022-09-13 14:33:21,291] {taskinstance.py:826} INFO - Dependencies all met for <TaskInstance: postgres_dag.create_employee_table 2022-09-12T03:00:00+00:00 [queued]>
[2022-09-13 14:33:21,366] {taskinstance.py:826} INFO - Dependencies all met for <TaskInstance: postgres_dag.create_employee_table 2022-09-12T03:00:00+00:00 [queued]>
[2022-09-13 14:33:21,369] {taskinstance.py:1017} INFO - 
--------------------------------------------------------------------------------
[2022-09-13 14:33:21,371] {taskinstance.py:1018} INFO - Starting attempt 2 of 3
[2022-09-13 14:33:21,373] {taskinstance.py:1019} INFO - 
--------------------------------------------------------------------------------
[2022-09-13 14:33:21,453] {taskinstance.py:1038} INFO - Executing <Task(PostgresOperator): create_employee_table> on 2022-09-12T03:00:00+00:00
[2022-09-13 14:33:21,467] {standard_task_runner.py:51} INFO - Started process 28726 to run task
[2022-09-13 14:33:21,493] {standard_task_runner.py:75} INFO - Running: ['airflow', 'tasks', 'run', 'postgres_dag', 'create_employee_table', '2022-09-12T03:00:00+00:00', '--job-id', '65', '--pool', 'default_pool', '--raw', '--subdir', 'DAGS_FOLDER/dag_with_postgres.py', '--cfg-path', '/tmp/tmp6jjsgytb']
[2022-09-13 14:33:21,511] {standard_task_runner.py:76} INFO - Job 65: Subtask create_employee_table
[2022-09-13 14:33:21,633] {logging_mixin.py:103} INFO - Running <TaskInstance: postgres_dag.create_employee_table 2022-09-12T03:00:00+00:00 [running]> on host 27377494ab8b
[2022-09-13 14:33:21,752] {taskinstance.py:1232} INFO - Exporting the following env vars:
AIRFLOW_CTX_DAG_OWNER=Dave
AIRFLOW_CTX_DAG_ID=postgres_dag
AIRFLOW_CTX_TASK_ID=create_employee_table
AIRFLOW_CTX_EXECUTION_DATE=2022-09-12T03:00:00+00:00
AIRFLOW_CTX_DAG_RUN_ID=scheduled__2022-09-12T03:00:00+00:00
[2022-09-13 14:33:21,755] {postgres.py:69} INFO - Executing: 
            create table if not exists employee(
                emp_id varchar,
                first_name varchar,
                last_name varchar,
                designation varchar
                primary key (emp_id)
            )
        
[2022-09-13 14:33:21,792] {base.py:74} INFO - Using connection to: id: local_postgres. Host: host.docker.internal, Port: 5432, Schema: student, Login: postgres, Password: XXXXXXXX, extra: None
[2022-09-13 14:33:21,804] {dbapi.py:180} INFO - Running statement: 
            create table if not exists employee(
                emp_id varchar,
                first_name varchar,
                last_name varchar,
                designation varchar
                primary key (emp_id)
            )
        , parameters: None
[2022-09-13 14:33:21,816] {taskinstance.py:1396} ERROR - syntax error at or near "("
LINE 7:                 primary key (emp_id)
                                    ^
Traceback (most recent call last):
  File "/home/airflow/.local/lib/python3.6/site-packages/airflow/models/taskinstance.py", line 1086, in _run_raw_task
    self._prepare_and_execute_task_with_callbacks(context, task)
  File "/home/airflow/.local/lib/python3.6/site-packages/airflow/models/taskinstance.py", line 1260, in _prepare_and_execute_task_with_callbacks
    result = self._execute_task(context, task_copy)
  File "/home/airflow/.local/lib/python3.6/site-packages/airflow/models/taskinstance.py", line 1300, in _execute_task
    result = task_copy.execute(context=context)
  File "/home/airflow/.local/lib/python3.6/site-packages/airflow/providers/postgres/operators/postgres.py", line 71, in execute
    self.hook.run(self.sql, self.autocommit, parameters=self.parameters)
  File "/home/airflow/.local/lib/python3.6/site-packages/airflow/hooks/dbapi.py", line 184, in run
    cur.execute(sql_statement)
psycopg2.errors.SyntaxError: syntax error at or near "("
LINE 7:                 primary key (emp_id)
                                    ^

[2022-09-13 14:33:21,828] {taskinstance.py:1440} INFO - Marking task as UP_FOR_RETRY. dag_id=postgres_dag, task_id=create_employee_table, execution_date=20220912T030000, start_date=20220913T143321, end_date=20220913T143321
[2022-09-13 14:33:21,898] {local_task_job.py:118} INFO - Task exited with return code 1
