[2022-09-13 13:36:15,765] {taskinstance.py:826} INFO - Dependencies all met for <TaskInstance: postgres_dag.insert_records 2022-09-11T03:00:00+00:00 [queued]>
[2022-09-13 13:36:16,029] {taskinstance.py:826} INFO - Dependencies all met for <TaskInstance: postgres_dag.insert_records 2022-09-11T03:00:00+00:00 [queued]>
[2022-09-13 13:36:16,032] {taskinstance.py:1017} INFO - 
--------------------------------------------------------------------------------
[2022-09-13 13:36:16,036] {taskinstance.py:1018} INFO - Starting attempt 1 of 3
[2022-09-13 13:36:16,037] {taskinstance.py:1019} INFO - 
--------------------------------------------------------------------------------
[2022-09-13 13:36:16,115] {taskinstance.py:1038} INFO - Executing <Task(PostgresOperator): insert_records> on 2022-09-11T03:00:00+00:00
[2022-09-13 13:36:16,130] {standard_task_runner.py:51} INFO - Started process 39519 to run task
[2022-09-13 13:36:16,152] {standard_task_runner.py:75} INFO - Running: ['airflow', 'tasks', 'run', 'postgres_dag', 'insert_records', '2022-09-11T03:00:00+00:00', '--job-id', '20', '--pool', 'default_pool', '--raw', '--subdir', 'DAGS_FOLDER/dag_with_postgres.py', '--cfg-path', '/tmp/tmp25hseos3']
[2022-09-13 13:36:16,167] {standard_task_runner.py:76} INFO - Job 20: Subtask insert_records
[2022-09-13 13:36:16,703] {logging_mixin.py:103} INFO - Running <TaskInstance: postgres_dag.insert_records 2022-09-11T03:00:00+00:00 [running]> on host 27377494ab8b
[2022-09-13 13:36:17,277] {taskinstance.py:1232} INFO - Exporting the following env vars:
AIRFLOW_CTX_DAG_OWNER=Dave
AIRFLOW_CTX_DAG_ID=postgres_dag
AIRFLOW_CTX_TASK_ID=insert_records
AIRFLOW_CTX_EXECUTION_DATE=2022-09-11T03:00:00+00:00
AIRFLOW_CTX_DAG_RUN_ID=scheduled__2022-09-11T03:00:00+00:00
[2022-09-13 13:36:17,284] {postgres.py:69} INFO - Executing: 
            INSERT INTO employee (emp_id,first_name,last_name,designation)
            VALUES ('l101','Bayo','Lanre','Software-developer');
            INSERT INTO employee (emp_id,first_name,last_name,designation)
            VALUES ('l1201','Diaz','Mora','Data Scientist');
            INSERT INTO employee (emp_id,first_name,last_name,designation)
            VALUES ('l4101','Chris','Muff','scrum-master');
            INSERT INTO employee (emp_id,first_name,last_name,designation)
            VALUES ('l1301','Inder','Ajith','Manager');
        
[2022-09-13 13:36:17,431] {base.py:74} INFO - Using connection to: id: local_postgres. Host: 0.0.0.0, Port: 5432, Schema: airflow, Login: postgres, Password: XXXXXXXX, extra: None
[2022-09-13 13:36:17,445] {taskinstance.py:1396} ERROR - could not connect to server: Connection refused
	Is the server running on host "0.0.0.0" and accepting
	TCP/IP connections on port 5432?
Traceback (most recent call last):
  File "/home/airflow/.local/lib/python3.6/site-packages/airflow/models/taskinstance.py", line 1086, in _run_raw_task
    self._prepare_and_execute_task_with_callbacks(context, task)
  File "/home/airflow/.local/lib/python3.6/site-packages/airflow/models/taskinstance.py", line 1260, in _prepare_and_execute_task_with_callbacks
    result = self._execute_task(context, task_copy)
  File "/home/airflow/.local/lib/python3.6/site-packages/airflow/models/taskinstance.py", line 1300, in _execute_task
    result = task_copy.execute(context=context)
  File "/home/airflow/.local/lib/python3.6/site-packages/airflow/providers/postgres/operators/postgres.py", line 71, in execute
    self.hook.run(self.sql, self.autocommit, parameters=self.parameters)
  File "/home/airflow/.local/lib/python3.6/site-packages/airflow/hooks/dbapi.py", line 173, in run
    with closing(self.get_conn()) as conn:
  File "/home/airflow/.local/lib/python3.6/site-packages/airflow/providers/postgres/hooks/postgres.py", line 108, in get_conn
    self.conn = psycopg2.connect(**conn_args)
  File "/home/airflow/.local/lib/python3.6/site-packages/psycopg2/__init__.py", line 127, in connect
    conn = _connect(dsn, connection_factory=connection_factory, **kwasync)
psycopg2.OperationalError: could not connect to server: Connection refused
	Is the server running on host "0.0.0.0" and accepting
	TCP/IP connections on port 5432?

[2022-09-13 13:36:17,474] {taskinstance.py:1440} INFO - Marking task as UP_FOR_RETRY. dag_id=postgres_dag, task_id=insert_records, execution_date=20220911T030000, start_date=20220913T133615, end_date=20220913T133617
[2022-09-13 13:36:17,639] {local_task_job.py:118} INFO - Task exited with return code 1
[2022-09-13 13:39:08,809] {taskinstance.py:826} INFO - Dependencies all met for <TaskInstance: postgres_dag.insert_records 2022-09-11T03:00:00+00:00 [queued]>
[2022-09-13 13:39:08,920] {taskinstance.py:826} INFO - Dependencies all met for <TaskInstance: postgres_dag.insert_records 2022-09-11T03:00:00+00:00 [queued]>
[2022-09-13 13:39:08,923] {taskinstance.py:1017} INFO - 
--------------------------------------------------------------------------------
[2022-09-13 13:39:08,924] {taskinstance.py:1018} INFO - Starting attempt 1 of 3
[2022-09-13 13:39:08,925] {taskinstance.py:1019} INFO - 
--------------------------------------------------------------------------------
[2022-09-13 13:39:09,056] {taskinstance.py:1038} INFO - Executing <Task(PostgresOperator): insert_records> on 2022-09-11T03:00:00+00:00
[2022-09-13 13:39:09,075] {standard_task_runner.py:51} INFO - Started process 42467 to run task
[2022-09-13 13:39:09,102] {standard_task_runner.py:75} INFO - Running: ['airflow', 'tasks', 'run', 'postgres_dag', 'insert_records', '2022-09-11T03:00:00+00:00', '--job-id', '44', '--pool', 'default_pool', '--raw', '--subdir', 'DAGS_FOLDER/dag_with_postgres.py', '--cfg-path', '/tmp/tmpidriuynh']
[2022-09-13 13:39:09,115] {standard_task_runner.py:76} INFO - Job 44: Subtask insert_records
[2022-09-13 13:39:09,535] {logging_mixin.py:103} INFO - Running <TaskInstance: postgres_dag.insert_records 2022-09-11T03:00:00+00:00 [running]> on host 27377494ab8b
[2022-09-13 13:39:09,930] {taskinstance.py:1232} INFO - Exporting the following env vars:
AIRFLOW_CTX_DAG_OWNER=Dave
AIRFLOW_CTX_DAG_ID=postgres_dag
AIRFLOW_CTX_TASK_ID=insert_records
AIRFLOW_CTX_EXECUTION_DATE=2022-09-11T03:00:00+00:00
AIRFLOW_CTX_DAG_RUN_ID=scheduled__2022-09-11T03:00:00+00:00
[2022-09-13 13:39:09,937] {postgres.py:69} INFO - Executing: 
            INSERT INTO employee (emp_id,first_name,last_name,designation)
            VALUES ('l101','Bayo','Lanre','Software-developer');
            INSERT INTO employee (emp_id,first_name,last_name,designation)
            VALUES ('l1201','Diaz','Mora','Data Scientist');
            INSERT INTO employee (emp_id,first_name,last_name,designation)
            VALUES ('l4101','Chris','Muff','scrum-master');
            INSERT INTO employee (emp_id,first_name,last_name,designation)
            VALUES ('l1301','Inder','Ajith','Manager');
        
[2022-09-13 13:39:10,108] {base.py:74} INFO - Using connection to: id: local_postgres. Host: host.docker.internal, Port: 5432, Schema: airflow, Login: postgres, Password: XXXXXXXX, extra: None
[2022-09-13 13:39:10,141] {taskinstance.py:1396} ERROR - FATAL:  database "airflow" does not exist
Traceback (most recent call last):
  File "/home/airflow/.local/lib/python3.6/site-packages/airflow/models/taskinstance.py", line 1086, in _run_raw_task
    self._prepare_and_execute_task_with_callbacks(context, task)
  File "/home/airflow/.local/lib/python3.6/site-packages/airflow/models/taskinstance.py", line 1260, in _prepare_and_execute_task_with_callbacks
    result = self._execute_task(context, task_copy)
  File "/home/airflow/.local/lib/python3.6/site-packages/airflow/models/taskinstance.py", line 1300, in _execute_task
    result = task_copy.execute(context=context)
  File "/home/airflow/.local/lib/python3.6/site-packages/airflow/providers/postgres/operators/postgres.py", line 71, in execute
    self.hook.run(self.sql, self.autocommit, parameters=self.parameters)
  File "/home/airflow/.local/lib/python3.6/site-packages/airflow/hooks/dbapi.py", line 173, in run
    with closing(self.get_conn()) as conn:
  File "/home/airflow/.local/lib/python3.6/site-packages/airflow/providers/postgres/hooks/postgres.py", line 108, in get_conn
    self.conn = psycopg2.connect(**conn_args)
  File "/home/airflow/.local/lib/python3.6/site-packages/psycopg2/__init__.py", line 127, in connect
    conn = _connect(dsn, connection_factory=connection_factory, **kwasync)
psycopg2.OperationalError: FATAL:  database "airflow" does not exist

[2022-09-13 13:39:10,165] {taskinstance.py:1440} INFO - Marking task as UP_FOR_RETRY. dag_id=postgres_dag, task_id=insert_records, execution_date=20220911T030000, start_date=20220913T133908, end_date=20220913T133910
[2022-09-13 13:39:10,602] {local_task_job.py:118} INFO - Task exited with return code 1
[2022-09-13 14:57:32,264] {taskinstance.py:826} INFO - Dependencies all met for <TaskInstance: postgres_dag.insert_records 2022-09-11T03:00:00+00:00 [queued]>
[2022-09-13 14:57:32,336] {taskinstance.py:826} INFO - Dependencies all met for <TaskInstance: postgres_dag.insert_records 2022-09-11T03:00:00+00:00 [queued]>
[2022-09-13 14:57:32,344] {taskinstance.py:1017} INFO - 
--------------------------------------------------------------------------------
[2022-09-13 14:57:32,346] {taskinstance.py:1018} INFO - Starting attempt 1 of 3
[2022-09-13 14:57:32,347] {taskinstance.py:1019} INFO - 
--------------------------------------------------------------------------------
[2022-09-13 14:57:32,387] {taskinstance.py:1038} INFO - Executing <Task(PostgresOperator): insert_records> on 2022-09-11T03:00:00+00:00
[2022-09-13 14:57:32,410] {standard_task_runner.py:51} INFO - Started process 58608 to run task
[2022-09-13 14:57:32,436] {standard_task_runner.py:75} INFO - Running: ['airflow', 'tasks', 'run', 'postgres_dag', 'insert_records', '2022-09-11T03:00:00+00:00', '--job-id', '78', '--pool', 'default_pool', '--raw', '--subdir', 'DAGS_FOLDER/dag_with_postgres.py', '--cfg-path', '/tmp/tmp51wihsy8']
[2022-09-13 14:57:32,445] {standard_task_runner.py:76} INFO - Job 78: Subtask insert_records
[2022-09-13 14:57:32,719] {logging_mixin.py:103} INFO - Running <TaskInstance: postgres_dag.insert_records 2022-09-11T03:00:00+00:00 [running]> on host 27377494ab8b
[2022-09-13 14:57:33,008] {taskinstance.py:1232} INFO - Exporting the following env vars:
AIRFLOW_CTX_DAG_OWNER=Dave
AIRFLOW_CTX_DAG_ID=postgres_dag
AIRFLOW_CTX_TASK_ID=insert_records
AIRFLOW_CTX_EXECUTION_DATE=2022-09-11T03:00:00+00:00
AIRFLOW_CTX_DAG_RUN_ID=scheduled__2022-09-11T03:00:00+00:00
[2022-09-13 14:57:33,012] {postgres.py:69} INFO - Executing: 
            INSERT INTO employee (emp_id,first_name,last_name,designation)
            VALUES ('l101','Bayo','Lanre','Software-developer');
            INSERT INTO employee (emp_id,first_name,last_name,designation)
            VALUES ('l1201','Diaz','Mora','Data Scientist');
            INSERT INTO employee (emp_id,first_name,last_name,designation)
            VALUES ('l4101','Chris','Muff','scrum-master');
            INSERT INTO employee (emp_id,first_name,last_name,designation)
            VALUES ('l1301','Inder','Ajith','Manager');
        
[2022-09-13 14:57:33,070] {base.py:74} INFO - Using connection to: id: local_postgres. Host: host.docker.internal, Port: 5432, Schema: student, Login: postgres, Password: XXXXXXXX, extra: None
[2022-09-13 14:57:33,121] {dbapi.py:180} INFO - Running statement: 
            INSERT INTO employee (emp_id,first_name,last_name,designation)
            VALUES ('l101','Bayo','Lanre','Software-developer');
            INSERT INTO employee (emp_id,first_name,last_name,designation)
            VALUES ('l1201','Diaz','Mora','Data Scientist');
            INSERT INTO employee (emp_id,first_name,last_name,designation)
            VALUES ('l4101','Chris','Muff','scrum-master');
            INSERT INTO employee (emp_id,first_name,last_name,designation)
            VALUES ('l1301','Inder','Ajith','Manager');
        , parameters: None
[2022-09-13 14:57:33,345] {taskinstance.py:1396} ERROR - duplicate key value violates unique constraint "employee_pkey"
DETAIL:  Key (emp_id)=(l101) already exists.
Traceback (most recent call last):
  File "/home/airflow/.local/lib/python3.6/site-packages/airflow/models/taskinstance.py", line 1086, in _run_raw_task
    self._prepare_and_execute_task_with_callbacks(context, task)
  File "/home/airflow/.local/lib/python3.6/site-packages/airflow/models/taskinstance.py", line 1260, in _prepare_and_execute_task_with_callbacks
    result = self._execute_task(context, task_copy)
  File "/home/airflow/.local/lib/python3.6/site-packages/airflow/models/taskinstance.py", line 1300, in _execute_task
    result = task_copy.execute(context=context)
  File "/home/airflow/.local/lib/python3.6/site-packages/airflow/providers/postgres/operators/postgres.py", line 71, in execute
    self.hook.run(self.sql, self.autocommit, parameters=self.parameters)
  File "/home/airflow/.local/lib/python3.6/site-packages/airflow/hooks/dbapi.py", line 184, in run
    cur.execute(sql_statement)
psycopg2.errors.UniqueViolation: duplicate key value violates unique constraint "employee_pkey"
DETAIL:  Key (emp_id)=(l101) already exists.

[2022-09-13 14:57:33,378] {taskinstance.py:1440} INFO - Marking task as UP_FOR_RETRY. dag_id=postgres_dag, task_id=insert_records, execution_date=20220911T030000, start_date=20220913T145732, end_date=20220913T145733
[2022-09-13 14:57:33,535] {local_task_job.py:118} INFO - Task exited with return code 1
