[2022-09-13 13:38:28,654] {taskinstance.py:826} INFO - Dependencies all met for <TaskInstance: postgres_dag.insert_records 2022-09-11T03:00:00+00:00 [queued]>
[2022-09-13 13:38:28,859] {taskinstance.py:826} INFO - Dependencies all met for <TaskInstance: postgres_dag.insert_records 2022-09-11T03:00:00+00:00 [queued]>
[2022-09-13 13:38:28,861] {taskinstance.py:1017} INFO - 
--------------------------------------------------------------------------------
[2022-09-13 13:38:28,865] {taskinstance.py:1018} INFO - Starting attempt 3 of 3
[2022-09-13 13:38:28,870] {taskinstance.py:1019} INFO - 
--------------------------------------------------------------------------------
[2022-09-13 13:38:28,961] {taskinstance.py:1038} INFO - Executing <Task(PostgresOperator): insert_records> on 2022-09-11T03:00:00+00:00
[2022-09-13 13:38:28,987] {standard_task_runner.py:51} INFO - Started process 41875 to run task
[2022-09-13 13:38:29,017] {standard_task_runner.py:75} INFO - Running: ['airflow', 'tasks', 'run', 'postgres_dag', 'insert_records', '2022-09-11T03:00:00+00:00', '--job-id', '36', '--pool', 'default_pool', '--raw', '--subdir', 'DAGS_FOLDER/dag_with_postgres.py', '--cfg-path', '/tmp/tmp5ebod7yg']
[2022-09-13 13:38:29,030] {standard_task_runner.py:76} INFO - Job 36: Subtask insert_records
[2022-09-13 13:38:29,472] {logging_mixin.py:103} INFO - Running <TaskInstance: postgres_dag.insert_records 2022-09-11T03:00:00+00:00 [running]> on host 27377494ab8b
[2022-09-13 13:38:29,881] {taskinstance.py:1232} INFO - Exporting the following env vars:
AIRFLOW_CTX_DAG_OWNER=Dave
AIRFLOW_CTX_DAG_ID=postgres_dag
AIRFLOW_CTX_TASK_ID=insert_records
AIRFLOW_CTX_EXECUTION_DATE=2022-09-11T03:00:00+00:00
AIRFLOW_CTX_DAG_RUN_ID=scheduled__2022-09-11T03:00:00+00:00
[2022-09-13 13:38:29,884] {postgres.py:69} INFO - Executing: 
            INSERT INTO employee (emp_id,first_name,last_name,designation)
            VALUES ('l101','Bayo','Lanre','Software-developer');
            INSERT INTO employee (emp_id,first_name,last_name,designation)
            VALUES ('l1201','Diaz','Mora','Data Scientist');
            INSERT INTO employee (emp_id,first_name,last_name,designation)
            VALUES ('l4101','Chris','Muff','scrum-master');
            INSERT INTO employee (emp_id,first_name,last_name,designation)
            VALUES ('l1301','Inder','Ajith','Manager');
        
[2022-09-13 13:38:30,016] {base.py:74} INFO - Using connection to: id: local_postgres. Host: host.docker.internal, Port: 5432, Schema: airflow, Login: postgres, Password: XXXXXXXX, extra: None
[2022-09-13 13:38:30,065] {taskinstance.py:1396} ERROR - FATAL:  database "airflow" does not exist
Traceback (most recent call last):
  File "/home/airflow/.local/lib/python3.6/site-packages/airflow/models/taskinstance.py", line 1086, in _run_raw_task
    self._prepare_and_execute_task_with_callbacks(context, task)
  File "/home/airflow/.local/lib/python3.6/site-packages/airflow/models/taskinstance.py", line 1260, in _prepare_and_execute_task_with_callbacks
    result = self._execute_task(context, task_copy)
  File "/home/airflow/.local/lib/python3.6/site-packages/airflow/models/taskinstance.py", line 1300, in _execute_task
    result = task_copy.execute(context=context)
  File "/home/airflow/.local/lib/python3.6/site-packages/airflow/providers/postgres/operators/postgres.py", line 71, in execute
    self.hook.run(self.sql, self.autocommit, parameters=self.parameters)
  File "/home/airflow/.local/lib/python3.6/site-packages/airflow/hooks/dbapi.py", line 173, in run
    with closing(self.get_conn()) as conn:
  File "/home/airflow/.local/lib/python3.6/site-packages/airflow/providers/postgres/hooks/postgres.py", line 108, in get_conn
    self.conn = psycopg2.connect(**conn_args)
  File "/home/airflow/.local/lib/python3.6/site-packages/psycopg2/__init__.py", line 127, in connect
    conn = _connect(dsn, connection_factory=connection_factory, **kwasync)
psycopg2.OperationalError: FATAL:  database "airflow" does not exist

[2022-09-13 13:38:30,117] {taskinstance.py:1440} INFO - Marking task as FAILED. dag_id=postgres_dag, task_id=insert_records, execution_date=20220911T030000, start_date=20220913T133828, end_date=20220913T133830
[2022-09-13 13:38:30,609] {local_task_job.py:118} INFO - Task exited with return code 1
[2022-09-13 14:59:40,215] {taskinstance.py:826} INFO - Dependencies all met for <TaskInstance: postgres_dag.insert_records 2022-09-11T03:00:00+00:00 [queued]>
[2022-09-13 14:59:40,312] {taskinstance.py:826} INFO - Dependencies all met for <TaskInstance: postgres_dag.insert_records 2022-09-11T03:00:00+00:00 [queued]>
[2022-09-13 14:59:40,315] {taskinstance.py:1017} INFO - 
--------------------------------------------------------------------------------
[2022-09-13 14:59:40,316] {taskinstance.py:1018} INFO - Starting attempt 3 of 3
[2022-09-13 14:59:40,317] {taskinstance.py:1019} INFO - 
--------------------------------------------------------------------------------
[2022-09-13 14:59:40,380] {taskinstance.py:1038} INFO - Executing <Task(PostgresOperator): insert_records> on 2022-09-11T03:00:00+00:00
[2022-09-13 14:59:40,400] {standard_task_runner.py:51} INFO - Started process 60999 to run task
[2022-09-13 14:59:40,418] {standard_task_runner.py:75} INFO - Running: ['airflow', 'tasks', 'run', 'postgres_dag', 'insert_records', '2022-09-11T03:00:00+00:00', '--job-id', '85', '--pool', 'default_pool', '--raw', '--subdir', 'DAGS_FOLDER/dag_with_postgres.py', '--cfg-path', '/tmp/tmpqefug9vl']
[2022-09-13 14:59:40,427] {standard_task_runner.py:76} INFO - Job 85: Subtask insert_records
[2022-09-13 14:59:41,948] {logging_mixin.py:103} INFO - Running <TaskInstance: postgres_dag.insert_records 2022-09-11T03:00:00+00:00 [running]> on host 27377494ab8b
[2022-09-13 14:59:42,202] {taskinstance.py:1232} INFO - Exporting the following env vars:
AIRFLOW_CTX_DAG_OWNER=Dave
AIRFLOW_CTX_DAG_ID=postgres_dag
AIRFLOW_CTX_TASK_ID=insert_records
AIRFLOW_CTX_EXECUTION_DATE=2022-09-11T03:00:00+00:00
AIRFLOW_CTX_DAG_RUN_ID=scheduled__2022-09-11T03:00:00+00:00
[2022-09-13 14:59:42,208] {postgres.py:69} INFO - Executing: 
            INSERT INTO employee (emp_id,first_name,last_name,designation)
            VALUES ('l101','Bayo','Lanre','Software-developer');
            INSERT INTO employee (emp_id,first_name,last_name,designation)
            VALUES ('l1201','Diaz','Mora','Data Scientist');
            INSERT INTO employee (emp_id,first_name,last_name,designation)
            VALUES ('l4101','Chris','Muff','scrum-master');
            INSERT INTO employee (emp_id,first_name,last_name,designation)
            VALUES ('l1301','Inder','Ajith','Manager');
        
[2022-09-13 14:59:42,322] {base.py:74} INFO - Using connection to: id: local_postgres. Host: host.docker.internal, Port: 5432, Schema: student, Login: postgres, Password: XXXXXXXX, extra: None
[2022-09-13 14:59:42,510] {dbapi.py:180} INFO - Running statement: 
            INSERT INTO employee (emp_id,first_name,last_name,designation)
            VALUES ('l101','Bayo','Lanre','Software-developer');
            INSERT INTO employee (emp_id,first_name,last_name,designation)
            VALUES ('l1201','Diaz','Mora','Data Scientist');
            INSERT INTO employee (emp_id,first_name,last_name,designation)
            VALUES ('l4101','Chris','Muff','scrum-master');
            INSERT INTO employee (emp_id,first_name,last_name,designation)
            VALUES ('l1301','Inder','Ajith','Manager');
        , parameters: None
[2022-09-13 14:59:42,564] {taskinstance.py:1396} ERROR - duplicate key value violates unique constraint "employee_pkey"
DETAIL:  Key (emp_id)=(l101) already exists.
Traceback (most recent call last):
  File "/home/airflow/.local/lib/python3.6/site-packages/airflow/models/taskinstance.py", line 1086, in _run_raw_task
    self._prepare_and_execute_task_with_callbacks(context, task)
  File "/home/airflow/.local/lib/python3.6/site-packages/airflow/models/taskinstance.py", line 1260, in _prepare_and_execute_task_with_callbacks
    result = self._execute_task(context, task_copy)
  File "/home/airflow/.local/lib/python3.6/site-packages/airflow/models/taskinstance.py", line 1300, in _execute_task
    result = task_copy.execute(context=context)
  File "/home/airflow/.local/lib/python3.6/site-packages/airflow/providers/postgres/operators/postgres.py", line 71, in execute
    self.hook.run(self.sql, self.autocommit, parameters=self.parameters)
  File "/home/airflow/.local/lib/python3.6/site-packages/airflow/hooks/dbapi.py", line 184, in run
    cur.execute(sql_statement)
psycopg2.errors.UniqueViolation: duplicate key value violates unique constraint "employee_pkey"
DETAIL:  Key (emp_id)=(l101) already exists.

[2022-09-13 14:59:42,585] {taskinstance.py:1440} INFO - Marking task as FAILED. dag_id=postgres_dag, task_id=insert_records, execution_date=20220911T030000, start_date=20220913T145940, end_date=20220913T145942
[2022-09-13 14:59:42,749] {local_task_job.py:118} INFO - Task exited with return code 1
