[2022-09-13 13:37:20,904] {taskinstance.py:826} INFO - Dependencies all met for <TaskInstance: postgres_dag.create_employee_table 2022-09-10T03:00:00+00:00 [queued]>
[2022-09-13 13:37:21,024] {taskinstance.py:826} INFO - Dependencies all met for <TaskInstance: postgres_dag.create_employee_table 2022-09-10T03:00:00+00:00 [queued]>
[2022-09-13 13:37:21,030] {taskinstance.py:1017} INFO - 
--------------------------------------------------------------------------------
[2022-09-13 13:37:21,039] {taskinstance.py:1018} INFO - Starting attempt 2 of 3
[2022-09-13 13:37:21,043] {taskinstance.py:1019} INFO - 
--------------------------------------------------------------------------------
[2022-09-13 13:37:21,129] {taskinstance.py:1038} INFO - Executing <Task(PostgresOperator): create_employee_table> on 2022-09-10T03:00:00+00:00
[2022-09-13 13:37:21,148] {standard_task_runner.py:51} INFO - Started process 40681 to run task
[2022-09-13 13:37:21,158] {standard_task_runner.py:75} INFO - Running: ['airflow', 'tasks', 'run', 'postgres_dag', 'create_employee_table', '2022-09-10T03:00:00+00:00', '--job-id', '26', '--pool', 'default_pool', '--raw', '--subdir', 'DAGS_FOLDER/dag_with_postgres.py', '--cfg-path', '/tmp/tmpnc8viihd']
[2022-09-13 13:37:21,170] {standard_task_runner.py:76} INFO - Job 26: Subtask create_employee_table
[2022-09-13 13:37:21,471] {logging_mixin.py:103} INFO - Running <TaskInstance: postgres_dag.create_employee_table 2022-09-10T03:00:00+00:00 [running]> on host 27377494ab8b
[2022-09-13 13:37:22,030] {taskinstance.py:1232} INFO - Exporting the following env vars:
AIRFLOW_CTX_DAG_OWNER=Dave
AIRFLOW_CTX_DAG_ID=postgres_dag
AIRFLOW_CTX_TASK_ID=create_employee_table
AIRFLOW_CTX_EXECUTION_DATE=2022-09-10T03:00:00+00:00
AIRFLOW_CTX_DAG_RUN_ID=scheduled__2022-09-10T03:00:00+00:00
[2022-09-13 13:37:22,034] {postgres.py:69} INFO - Executing: 
            create table if not exists employee(
                emp_id varchar,
                first_name varchar,
                last_name varchar,
                designation varchar
                primary key (emp_id)
            )
        
[2022-09-13 13:37:22,107] {base.py:74} INFO - Using connection to: id: local_postgres. Host: 0.0.0.0, Port: 5432, Schema: airflow, Login: postgres, Password: XXXXXXXX, extra: None
[2022-09-13 13:37:22,122] {taskinstance.py:1396} ERROR - could not connect to server: Connection refused
	Is the server running on host "0.0.0.0" and accepting
	TCP/IP connections on port 5432?
Traceback (most recent call last):
  File "/home/airflow/.local/lib/python3.6/site-packages/airflow/models/taskinstance.py", line 1086, in _run_raw_task
    self._prepare_and_execute_task_with_callbacks(context, task)
  File "/home/airflow/.local/lib/python3.6/site-packages/airflow/models/taskinstance.py", line 1260, in _prepare_and_execute_task_with_callbacks
    result = self._execute_task(context, task_copy)
  File "/home/airflow/.local/lib/python3.6/site-packages/airflow/models/taskinstance.py", line 1300, in _execute_task
    result = task_copy.execute(context=context)
  File "/home/airflow/.local/lib/python3.6/site-packages/airflow/providers/postgres/operators/postgres.py", line 71, in execute
    self.hook.run(self.sql, self.autocommit, parameters=self.parameters)
  File "/home/airflow/.local/lib/python3.6/site-packages/airflow/hooks/dbapi.py", line 173, in run
    with closing(self.get_conn()) as conn:
  File "/home/airflow/.local/lib/python3.6/site-packages/airflow/providers/postgres/hooks/postgres.py", line 108, in get_conn
    self.conn = psycopg2.connect(**conn_args)
  File "/home/airflow/.local/lib/python3.6/site-packages/psycopg2/__init__.py", line 127, in connect
    conn = _connect(dsn, connection_factory=connection_factory, **kwasync)
psycopg2.OperationalError: could not connect to server: Connection refused
	Is the server running on host "0.0.0.0" and accepting
	TCP/IP connections on port 5432?

[2022-09-13 13:37:22,144] {taskinstance.py:1440} INFO - Marking task as UP_FOR_RETRY. dag_id=postgres_dag, task_id=create_employee_table, execution_date=20220910T030000, start_date=20220913T133720, end_date=20220913T133722
[2022-09-13 13:37:22,388] {local_task_job.py:118} INFO - Task exited with return code 1
[2022-09-13 13:40:08,676] {taskinstance.py:826} INFO - Dependencies all met for <TaskInstance: postgres_dag.create_employee_table 2022-09-10T03:00:00+00:00 [queued]>
[2022-09-13 13:40:08,745] {taskinstance.py:826} INFO - Dependencies all met for <TaskInstance: postgres_dag.create_employee_table 2022-09-10T03:00:00+00:00 [queued]>
[2022-09-13 13:40:08,748] {taskinstance.py:1017} INFO - 
--------------------------------------------------------------------------------
[2022-09-13 13:40:08,750] {taskinstance.py:1018} INFO - Starting attempt 2 of 3
[2022-09-13 13:40:08,752] {taskinstance.py:1019} INFO - 
--------------------------------------------------------------------------------
[2022-09-13 13:40:08,803] {taskinstance.py:1038} INFO - Executing <Task(PostgresOperator): create_employee_table> on 2022-09-10T03:00:00+00:00
[2022-09-13 13:40:08,816] {standard_task_runner.py:51} INFO - Started process 43489 to run task
[2022-09-13 13:40:08,830] {standard_task_runner.py:75} INFO - Running: ['airflow', 'tasks', 'run', 'postgres_dag', 'create_employee_table', '2022-09-10T03:00:00+00:00', '--job-id', '49', '--pool', 'default_pool', '--raw', '--subdir', 'DAGS_FOLDER/dag_with_postgres.py', '--cfg-path', '/tmp/tmpge8blxty']
[2022-09-13 13:40:08,838] {standard_task_runner.py:76} INFO - Job 49: Subtask create_employee_table
[2022-09-13 13:40:08,953] {logging_mixin.py:103} INFO - Running <TaskInstance: postgres_dag.create_employee_table 2022-09-10T03:00:00+00:00 [running]> on host 27377494ab8b
[2022-09-13 13:40:09,069] {taskinstance.py:1232} INFO - Exporting the following env vars:
AIRFLOW_CTX_DAG_OWNER=Dave
AIRFLOW_CTX_DAG_ID=postgres_dag
AIRFLOW_CTX_TASK_ID=create_employee_table
AIRFLOW_CTX_EXECUTION_DATE=2022-09-10T03:00:00+00:00
AIRFLOW_CTX_DAG_RUN_ID=scheduled__2022-09-10T03:00:00+00:00
[2022-09-13 13:40:09,072] {postgres.py:69} INFO - Executing: 
            create table if not exists employee(
                emp_id varchar,
                first_name varchar,
                last_name varchar,
                designation varchar
                primary key (emp_id)
            )
        
[2022-09-13 13:40:09,109] {base.py:74} INFO - Using connection to: id: local_postgres. Host: host.docker.internal, Port: 5432, Schema: airflow, Login: postgres, Password: XXXXXXXX, extra: None
[2022-09-13 13:40:09,136] {taskinstance.py:1396} ERROR - FATAL:  database "airflow" does not exist
Traceback (most recent call last):
  File "/home/airflow/.local/lib/python3.6/site-packages/airflow/models/taskinstance.py", line 1086, in _run_raw_task
    self._prepare_and_execute_task_with_callbacks(context, task)
  File "/home/airflow/.local/lib/python3.6/site-packages/airflow/models/taskinstance.py", line 1260, in _prepare_and_execute_task_with_callbacks
    result = self._execute_task(context, task_copy)
  File "/home/airflow/.local/lib/python3.6/site-packages/airflow/models/taskinstance.py", line 1300, in _execute_task
    result = task_copy.execute(context=context)
  File "/home/airflow/.local/lib/python3.6/site-packages/airflow/providers/postgres/operators/postgres.py", line 71, in execute
    self.hook.run(self.sql, self.autocommit, parameters=self.parameters)
  File "/home/airflow/.local/lib/python3.6/site-packages/airflow/hooks/dbapi.py", line 173, in run
    with closing(self.get_conn()) as conn:
  File "/home/airflow/.local/lib/python3.6/site-packages/airflow/providers/postgres/hooks/postgres.py", line 108, in get_conn
    self.conn = psycopg2.connect(**conn_args)
  File "/home/airflow/.local/lib/python3.6/site-packages/psycopg2/__init__.py", line 127, in connect
    conn = _connect(dsn, connection_factory=connection_factory, **kwasync)
psycopg2.OperationalError: FATAL:  database "airflow" does not exist

[2022-09-13 13:40:09,150] {taskinstance.py:1440} INFO - Marking task as UP_FOR_RETRY. dag_id=postgres_dag, task_id=create_employee_table, execution_date=20220910T030000, start_date=20220913T134008, end_date=20220913T134009
[2022-09-13 13:40:09,240] {local_task_job.py:118} INFO - Task exited with return code 1
[2022-09-13 14:33:19,756] {taskinstance.py:826} INFO - Dependencies all met for <TaskInstance: postgres_dag.create_employee_table 2022-09-10T03:00:00+00:00 [queued]>
[2022-09-13 14:33:19,796] {taskinstance.py:826} INFO - Dependencies all met for <TaskInstance: postgres_dag.create_employee_table 2022-09-10T03:00:00+00:00 [queued]>
[2022-09-13 14:33:19,798] {taskinstance.py:1017} INFO - 
--------------------------------------------------------------------------------
[2022-09-13 14:33:19,799] {taskinstance.py:1018} INFO - Starting attempt 2 of 3
[2022-09-13 14:33:19,800] {taskinstance.py:1019} INFO - 
--------------------------------------------------------------------------------
[2022-09-13 14:33:19,860] {taskinstance.py:1038} INFO - Executing <Task(PostgresOperator): create_employee_table> on 2022-09-10T03:00:00+00:00
[2022-09-13 14:33:19,869] {standard_task_runner.py:51} INFO - Started process 28694 to run task
[2022-09-13 14:33:19,890] {standard_task_runner.py:75} INFO - Running: ['airflow', 'tasks', 'run', 'postgres_dag', 'create_employee_table', '2022-09-10T03:00:00+00:00', '--job-id', '63', '--pool', 'default_pool', '--raw', '--subdir', 'DAGS_FOLDER/dag_with_postgres.py', '--cfg-path', '/tmp/tmpjp7rxael']
[2022-09-13 14:33:19,913] {standard_task_runner.py:76} INFO - Job 63: Subtask create_employee_table
[2022-09-13 14:33:20,095] {logging_mixin.py:103} INFO - Running <TaskInstance: postgres_dag.create_employee_table 2022-09-10T03:00:00+00:00 [running]> on host 27377494ab8b
[2022-09-13 14:33:20,212] {taskinstance.py:1232} INFO - Exporting the following env vars:
AIRFLOW_CTX_DAG_OWNER=Dave
AIRFLOW_CTX_DAG_ID=postgres_dag
AIRFLOW_CTX_TASK_ID=create_employee_table
AIRFLOW_CTX_EXECUTION_DATE=2022-09-10T03:00:00+00:00
AIRFLOW_CTX_DAG_RUN_ID=scheduled__2022-09-10T03:00:00+00:00
[2022-09-13 14:33:20,214] {postgres.py:69} INFO - Executing: 
            create table if not exists employee(
                emp_id varchar,
                first_name varchar,
                last_name varchar,
                designation varchar
                primary key (emp_id)
            )
        
[2022-09-13 14:33:20,252] {base.py:74} INFO - Using connection to: id: local_postgres. Host: host.docker.internal, Port: 5432, Schema: student, Login: postgres, Password: XXXXXXXX, extra: None
[2022-09-13 14:33:20,283] {dbapi.py:180} INFO - Running statement: 
            create table if not exists employee(
                emp_id varchar,
                first_name varchar,
                last_name varchar,
                designation varchar
                primary key (emp_id)
            )
        , parameters: None
[2022-09-13 14:33:20,288] {taskinstance.py:1396} ERROR - syntax error at or near "("
LINE 7:                 primary key (emp_id)
                                    ^
Traceback (most recent call last):
  File "/home/airflow/.local/lib/python3.6/site-packages/airflow/models/taskinstance.py", line 1086, in _run_raw_task
    self._prepare_and_execute_task_with_callbacks(context, task)
  File "/home/airflow/.local/lib/python3.6/site-packages/airflow/models/taskinstance.py", line 1260, in _prepare_and_execute_task_with_callbacks
    result = self._execute_task(context, task_copy)
  File "/home/airflow/.local/lib/python3.6/site-packages/airflow/models/taskinstance.py", line 1300, in _execute_task
    result = task_copy.execute(context=context)
  File "/home/airflow/.local/lib/python3.6/site-packages/airflow/providers/postgres/operators/postgres.py", line 71, in execute
    self.hook.run(self.sql, self.autocommit, parameters=self.parameters)
  File "/home/airflow/.local/lib/python3.6/site-packages/airflow/hooks/dbapi.py", line 184, in run
    cur.execute(sql_statement)
psycopg2.errors.SyntaxError: syntax error at or near "("
LINE 7:                 primary key (emp_id)
                                    ^

[2022-09-13 14:33:20,308] {taskinstance.py:1440} INFO - Marking task as UP_FOR_RETRY. dag_id=postgres_dag, task_id=create_employee_table, execution_date=20220910T030000, start_date=20220913T143319, end_date=20220913T143320
[2022-09-13 14:33:20,384] {local_task_job.py:118} INFO - Task exited with return code 1
