[2022-09-13 13:38:24,529] {taskinstance.py:826} INFO - Dependencies all met for <TaskInstance: postgres_dag.create_employee_table 2022-09-10T03:00:00+00:00 [queued]>
[2022-09-13 13:38:24,611] {taskinstance.py:826} INFO - Dependencies all met for <TaskInstance: postgres_dag.create_employee_table 2022-09-10T03:00:00+00:00 [queued]>
[2022-09-13 13:38:24,615] {taskinstance.py:1017} INFO - 
--------------------------------------------------------------------------------
[2022-09-13 13:38:24,621] {taskinstance.py:1018} INFO - Starting attempt 3 of 3
[2022-09-13 13:38:24,623] {taskinstance.py:1019} INFO - 
--------------------------------------------------------------------------------
[2022-09-13 13:38:24,674] {taskinstance.py:1038} INFO - Executing <Task(PostgresOperator): create_employee_table> on 2022-09-10T03:00:00+00:00
[2022-09-13 13:38:24,684] {standard_task_runner.py:51} INFO - Started process 41839 to run task
[2022-09-13 13:38:24,712] {standard_task_runner.py:75} INFO - Running: ['airflow', 'tasks', 'run', 'postgres_dag', 'create_employee_table', '2022-09-10T03:00:00+00:00', '--job-id', '33', '--pool', 'default_pool', '--raw', '--subdir', 'DAGS_FOLDER/dag_with_postgres.py', '--cfg-path', '/tmp/tmpc5zat836']
[2022-09-13 13:38:24,723] {standard_task_runner.py:76} INFO - Job 33: Subtask create_employee_table
[2022-09-13 13:38:25,135] {logging_mixin.py:103} INFO - Running <TaskInstance: postgres_dag.create_employee_table 2022-09-10T03:00:00+00:00 [running]> on host 27377494ab8b
[2022-09-13 13:38:25,599] {taskinstance.py:1232} INFO - Exporting the following env vars:
AIRFLOW_CTX_DAG_OWNER=Dave
AIRFLOW_CTX_DAG_ID=postgres_dag
AIRFLOW_CTX_TASK_ID=create_employee_table
AIRFLOW_CTX_EXECUTION_DATE=2022-09-10T03:00:00+00:00
AIRFLOW_CTX_DAG_RUN_ID=scheduled__2022-09-10T03:00:00+00:00
[2022-09-13 13:38:25,616] {postgres.py:69} INFO - Executing: 
            create table if not exists employee(
                emp_id varchar,
                first_name varchar,
                last_name varchar,
                designation varchar
                primary key (emp_id)
            )
        
[2022-09-13 13:38:25,832] {base.py:74} INFO - Using connection to: id: local_postgres. Host: 0.0.0.0, Port: 5432, Schema: airflow, Login: postgres, Password: XXXXXXXX, extra: None
[2022-09-13 13:38:25,850] {taskinstance.py:1396} ERROR - could not connect to server: Connection refused
	Is the server running on host "0.0.0.0" and accepting
	TCP/IP connections on port 5432?
Traceback (most recent call last):
  File "/home/airflow/.local/lib/python3.6/site-packages/airflow/models/taskinstance.py", line 1086, in _run_raw_task
    self._prepare_and_execute_task_with_callbacks(context, task)
  File "/home/airflow/.local/lib/python3.6/site-packages/airflow/models/taskinstance.py", line 1260, in _prepare_and_execute_task_with_callbacks
    result = self._execute_task(context, task_copy)
  File "/home/airflow/.local/lib/python3.6/site-packages/airflow/models/taskinstance.py", line 1300, in _execute_task
    result = task_copy.execute(context=context)
  File "/home/airflow/.local/lib/python3.6/site-packages/airflow/providers/postgres/operators/postgres.py", line 71, in execute
    self.hook.run(self.sql, self.autocommit, parameters=self.parameters)
  File "/home/airflow/.local/lib/python3.6/site-packages/airflow/hooks/dbapi.py", line 173, in run
    with closing(self.get_conn()) as conn:
  File "/home/airflow/.local/lib/python3.6/site-packages/airflow/providers/postgres/hooks/postgres.py", line 108, in get_conn
    self.conn = psycopg2.connect(**conn_args)
  File "/home/airflow/.local/lib/python3.6/site-packages/psycopg2/__init__.py", line 127, in connect
    conn = _connect(dsn, connection_factory=connection_factory, **kwasync)
psycopg2.OperationalError: could not connect to server: Connection refused
	Is the server running on host "0.0.0.0" and accepting
	TCP/IP connections on port 5432?

[2022-09-13 13:38:25,883] {taskinstance.py:1440} INFO - Marking task as FAILED. dag_id=postgres_dag, task_id=create_employee_table, execution_date=20220910T030000, start_date=20220913T133824, end_date=20220913T133825
[2022-09-13 13:38:26,172] {local_task_job.py:118} INFO - Task exited with return code 1
[2022-09-13 13:41:11,575] {taskinstance.py:826} INFO - Dependencies all met for <TaskInstance: postgres_dag.create_employee_table 2022-09-10T03:00:00+00:00 [queued]>
[2022-09-13 13:41:11,632] {taskinstance.py:826} INFO - Dependencies all met for <TaskInstance: postgres_dag.create_employee_table 2022-09-10T03:00:00+00:00 [queued]>
[2022-09-13 13:41:11,638] {taskinstance.py:1017} INFO - 
--------------------------------------------------------------------------------
[2022-09-13 13:41:11,641] {taskinstance.py:1018} INFO - Starting attempt 3 of 3
[2022-09-13 13:41:11,644] {taskinstance.py:1019} INFO - 
--------------------------------------------------------------------------------
[2022-09-13 13:41:11,684] {taskinstance.py:1038} INFO - Executing <Task(PostgresOperator): create_employee_table> on 2022-09-10T03:00:00+00:00
[2022-09-13 13:41:11,695] {standard_task_runner.py:51} INFO - Started process 44597 to run task
[2022-09-13 13:41:11,708] {standard_task_runner.py:75} INFO - Running: ['airflow', 'tasks', 'run', 'postgres_dag', 'create_employee_table', '2022-09-10T03:00:00+00:00', '--job-id', '53', '--pool', 'default_pool', '--raw', '--subdir', 'DAGS_FOLDER/dag_with_postgres.py', '--cfg-path', '/tmp/tmpt3yxgmnp']
[2022-09-13 13:41:11,714] {standard_task_runner.py:76} INFO - Job 53: Subtask create_employee_table
[2022-09-13 13:41:11,846] {logging_mixin.py:103} INFO - Running <TaskInstance: postgres_dag.create_employee_table 2022-09-10T03:00:00+00:00 [running]> on host 27377494ab8b
[2022-09-13 13:41:12,028] {taskinstance.py:1232} INFO - Exporting the following env vars:
AIRFLOW_CTX_DAG_OWNER=Dave
AIRFLOW_CTX_DAG_ID=postgres_dag
AIRFLOW_CTX_TASK_ID=create_employee_table
AIRFLOW_CTX_EXECUTION_DATE=2022-09-10T03:00:00+00:00
AIRFLOW_CTX_DAG_RUN_ID=scheduled__2022-09-10T03:00:00+00:00
[2022-09-13 13:41:12,047] {postgres.py:69} INFO - Executing: 
            create table if not exists employee(
                emp_id varchar,
                first_name varchar,
                last_name varchar,
                designation varchar
                primary key (emp_id)
            )
        
[2022-09-13 13:41:12,106] {base.py:74} INFO - Using connection to: id: local_postgres. Host: host.docker.internal, Port: 5432, Schema: airflow, Login: postgres, Password: XXXXXXXX, extra: None
[2022-09-13 13:41:12,136] {taskinstance.py:1396} ERROR - FATAL:  database "airflow" does not exist
Traceback (most recent call last):
  File "/home/airflow/.local/lib/python3.6/site-packages/airflow/models/taskinstance.py", line 1086, in _run_raw_task
    self._prepare_and_execute_task_with_callbacks(context, task)
  File "/home/airflow/.local/lib/python3.6/site-packages/airflow/models/taskinstance.py", line 1260, in _prepare_and_execute_task_with_callbacks
    result = self._execute_task(context, task_copy)
  File "/home/airflow/.local/lib/python3.6/site-packages/airflow/models/taskinstance.py", line 1300, in _execute_task
    result = task_copy.execute(context=context)
  File "/home/airflow/.local/lib/python3.6/site-packages/airflow/providers/postgres/operators/postgres.py", line 71, in execute
    self.hook.run(self.sql, self.autocommit, parameters=self.parameters)
  File "/home/airflow/.local/lib/python3.6/site-packages/airflow/hooks/dbapi.py", line 173, in run
    with closing(self.get_conn()) as conn:
  File "/home/airflow/.local/lib/python3.6/site-packages/airflow/providers/postgres/hooks/postgres.py", line 108, in get_conn
    self.conn = psycopg2.connect(**conn_args)
  File "/home/airflow/.local/lib/python3.6/site-packages/psycopg2/__init__.py", line 127, in connect
    conn = _connect(dsn, connection_factory=connection_factory, **kwasync)
psycopg2.OperationalError: FATAL:  database "airflow" does not exist

[2022-09-13 13:41:12,147] {taskinstance.py:1440} INFO - Marking task as FAILED. dag_id=postgres_dag, task_id=create_employee_table, execution_date=20220910T030000, start_date=20220913T134111, end_date=20220913T134112
[2022-09-13 13:41:12,240] {local_task_job.py:118} INFO - Task exited with return code 1
[2022-09-13 14:34:22,265] {taskinstance.py:826} INFO - Dependencies all met for <TaskInstance: postgres_dag.create_employee_table 2022-09-10T03:00:00+00:00 [queued]>
[2022-09-13 14:34:22,310] {taskinstance.py:826} INFO - Dependencies all met for <TaskInstance: postgres_dag.create_employee_table 2022-09-10T03:00:00+00:00 [queued]>
[2022-09-13 14:34:22,311] {taskinstance.py:1017} INFO - 
--------------------------------------------------------------------------------
[2022-09-13 14:34:22,312] {taskinstance.py:1018} INFO - Starting attempt 3 of 3
[2022-09-13 14:34:22,313] {taskinstance.py:1019} INFO - 
--------------------------------------------------------------------------------
[2022-09-13 14:34:22,339] {taskinstance.py:1038} INFO - Executing <Task(PostgresOperator): create_employee_table> on 2022-09-10T03:00:00+00:00
[2022-09-13 14:34:22,348] {standard_task_runner.py:51} INFO - Started process 29892 to run task
[2022-09-13 14:34:22,358] {standard_task_runner.py:75} INFO - Running: ['airflow', 'tasks', 'run', 'postgres_dag', 'create_employee_table', '2022-09-10T03:00:00+00:00', '--job-id', '67', '--pool', 'default_pool', '--raw', '--subdir', 'DAGS_FOLDER/dag_with_postgres.py', '--cfg-path', '/tmp/tmpewncu5z5']
[2022-09-13 14:34:22,367] {standard_task_runner.py:76} INFO - Job 67: Subtask create_employee_table
[2022-09-13 14:34:22,485] {logging_mixin.py:103} INFO - Running <TaskInstance: postgres_dag.create_employee_table 2022-09-10T03:00:00+00:00 [running]> on host 27377494ab8b
[2022-09-13 14:34:22,601] {taskinstance.py:1232} INFO - Exporting the following env vars:
AIRFLOW_CTX_DAG_OWNER=Dave
AIRFLOW_CTX_DAG_ID=postgres_dag
AIRFLOW_CTX_TASK_ID=create_employee_table
AIRFLOW_CTX_EXECUTION_DATE=2022-09-10T03:00:00+00:00
AIRFLOW_CTX_DAG_RUN_ID=scheduled__2022-09-10T03:00:00+00:00
[2022-09-13 14:34:22,605] {postgres.py:69} INFO - Executing: 
            create table if not exists employee(
                emp_id varchar,
                first_name varchar,
                last_name varchar,
                designation varchar
                primary key (emp_id)
            )
        
[2022-09-13 14:34:22,648] {base.py:74} INFO - Using connection to: id: local_postgres. Host: host.docker.internal, Port: 5432, Schema: student, Login: postgres, Password: XXXXXXXX, extra: None
[2022-09-13 14:34:22,824] {dbapi.py:180} INFO - Running statement: 
            create table if not exists employee(
                emp_id varchar,
                first_name varchar,
                last_name varchar,
                designation varchar
                primary key (emp_id)
            )
        , parameters: None
[2022-09-13 14:34:22,846] {taskinstance.py:1396} ERROR - syntax error at or near "("
LINE 7:                 primary key (emp_id)
                                    ^
Traceback (most recent call last):
  File "/home/airflow/.local/lib/python3.6/site-packages/airflow/models/taskinstance.py", line 1086, in _run_raw_task
    self._prepare_and_execute_task_with_callbacks(context, task)
  File "/home/airflow/.local/lib/python3.6/site-packages/airflow/models/taskinstance.py", line 1260, in _prepare_and_execute_task_with_callbacks
    result = self._execute_task(context, task_copy)
  File "/home/airflow/.local/lib/python3.6/site-packages/airflow/models/taskinstance.py", line 1300, in _execute_task
    result = task_copy.execute(context=context)
  File "/home/airflow/.local/lib/python3.6/site-packages/airflow/providers/postgres/operators/postgres.py", line 71, in execute
    self.hook.run(self.sql, self.autocommit, parameters=self.parameters)
  File "/home/airflow/.local/lib/python3.6/site-packages/airflow/hooks/dbapi.py", line 184, in run
    cur.execute(sql_statement)
psycopg2.errors.SyntaxError: syntax error at or near "("
LINE 7:                 primary key (emp_id)
                                    ^

[2022-09-13 14:34:22,862] {taskinstance.py:1440} INFO - Marking task as FAILED. dag_id=postgres_dag, task_id=create_employee_table, execution_date=20220910T030000, start_date=20220913T143422, end_date=20220913T143422
[2022-09-13 14:34:22,939] {local_task_job.py:118} INFO - Task exited with return code 1
