[2022-09-13 13:33:48,980] {taskinstance.py:826} INFO - Dependencies all met for <TaskInstance: postgres_dag.insert_records 2022-09-13T13:32:28.505548+00:00 [queued]>
[2022-09-13 13:33:49,093] {taskinstance.py:826} INFO - Dependencies all met for <TaskInstance: postgres_dag.insert_records 2022-09-13T13:32:28.505548+00:00 [queued]>
[2022-09-13 13:33:49,095] {taskinstance.py:1017} INFO - 
--------------------------------------------------------------------------------
[2022-09-13 13:33:49,100] {taskinstance.py:1018} INFO - Starting attempt 1 of 3
[2022-09-13 13:33:49,102] {taskinstance.py:1019} INFO - 
--------------------------------------------------------------------------------
[2022-09-13 13:33:49,164] {taskinstance.py:1038} INFO - Executing <Task(PostgresOperator): insert_records> on 2022-09-13T13:32:28.505548+00:00
[2022-09-13 13:33:49,175] {standard_task_runner.py:51} INFO - Started process 36838 to run task
[2022-09-13 13:33:49,252] {standard_task_runner.py:75} INFO - Running: ['airflow', 'tasks', 'run', 'postgres_dag', 'insert_records', '2022-09-13T13:32:28.505548+00:00', '--job-id', '13', '--pool', 'default_pool', '--raw', '--subdir', 'DAGS_FOLDER/dag_with_postgres.py', '--cfg-path', '/tmp/tmpi9vywx7u']
[2022-09-13 13:33:49,274] {standard_task_runner.py:76} INFO - Job 13: Subtask insert_records
[2022-09-13 13:33:49,775] {logging_mixin.py:103} INFO - Running <TaskInstance: postgres_dag.insert_records 2022-09-13T13:32:28.505548+00:00 [running]> on host 27377494ab8b
[2022-09-13 13:33:50,343] {taskinstance.py:1232} INFO - Exporting the following env vars:
AIRFLOW_CTX_DAG_OWNER=Dave
AIRFLOW_CTX_DAG_ID=postgres_dag
AIRFLOW_CTX_TASK_ID=insert_records
AIRFLOW_CTX_EXECUTION_DATE=2022-09-13T13:32:28.505548+00:00
AIRFLOW_CTX_DAG_RUN_ID=manual__2022-09-13T13:32:28.505548+00:00
[2022-09-13 13:33:50,355] {postgres.py:69} INFO - Executing: 
            INSERT INTO employee (emp_id,first_name,last_name,designation)
            VALUES ('l101','Bayo','Lanre','Software-developer');
            INSERT INTO employee (emp_id,first_name,last_name,designation)
            VALUES ('l1201','Diaz','Mora','Data Scientist');
            INSERT INTO employee (emp_id,first_name,last_name,designation)
            VALUES ('l4101','Chris','Muff','scrum-master');
            INSERT INTO employee (emp_id,first_name,last_name,designation)
            VALUES ('l1301','Inder','Ajith','Manager');
        
[2022-09-13 13:33:50,476] {base.py:74} INFO - Using connection to: id: local_postgres. Host: host.docker.local, Port: 5432, Schema: airflow, Login: postgres, Password: XXXXXXXX, extra: None
[2022-09-13 13:34:00,500] {taskinstance.py:1396} ERROR - could not translate host name "host.docker.local" to address: Temporary failure in name resolution
Traceback (most recent call last):
  File "/home/airflow/.local/lib/python3.6/site-packages/airflow/models/taskinstance.py", line 1086, in _run_raw_task
    self._prepare_and_execute_task_with_callbacks(context, task)
  File "/home/airflow/.local/lib/python3.6/site-packages/airflow/models/taskinstance.py", line 1260, in _prepare_and_execute_task_with_callbacks
    result = self._execute_task(context, task_copy)
  File "/home/airflow/.local/lib/python3.6/site-packages/airflow/models/taskinstance.py", line 1300, in _execute_task
    result = task_copy.execute(context=context)
  File "/home/airflow/.local/lib/python3.6/site-packages/airflow/providers/postgres/operators/postgres.py", line 71, in execute
    self.hook.run(self.sql, self.autocommit, parameters=self.parameters)
  File "/home/airflow/.local/lib/python3.6/site-packages/airflow/hooks/dbapi.py", line 173, in run
    with closing(self.get_conn()) as conn:
  File "/home/airflow/.local/lib/python3.6/site-packages/airflow/providers/postgres/hooks/postgres.py", line 108, in get_conn
    self.conn = psycopg2.connect(**conn_args)
  File "/home/airflow/.local/lib/python3.6/site-packages/psycopg2/__init__.py", line 127, in connect
    conn = _connect(dsn, connection_factory=connection_factory, **kwasync)
psycopg2.OperationalError: could not translate host name "host.docker.local" to address: Temporary failure in name resolution

[2022-09-13 13:34:00,528] {taskinstance.py:1440} INFO - Marking task as UP_FOR_RETRY. dag_id=postgres_dag, task_id=insert_records, execution_date=20220913T133228, start_date=20220913T133348, end_date=20220913T133400
[2022-09-13 13:34:00,632] {local_task_job.py:118} INFO - Task exited with return code 1
